
[     UTC     ] Logs for cardio-riskanalyzer.streamlit.app/
────────────────────────────────────────────────────────────────────────────────────────
[22:18:34] 🖥 Provisioning machine...
[22:18:34] 🎛 Preparing system...
[22:18:34] ⛓ Spinning up manager process...
[22:18:39] 🚀 Starting up repository: 'cardioriskanalyzer', branch: 'main', main module: 'scripts/heart_disease_prediction.py'
[22:18:39] 🐙 Cloning repository...
[22:18:52] 🐙 Cloning into '/mount/src/cardioriskanalyzer'...
Warning: Permanently added the ED25519 host key for IP address '192.30.255.113' to the list of known hosts.
Filtering content: 100% (2/2), 547.50 MiB | 52.49 MiB/sFiltering content: 100% (2/2), 547.50 MiB | 46.12 MiB/s, done.

[22:18:52] 🐙 Cloned repository!
[22:18:52] 🐙 Pulling code changes from Github...
[22:19:03] 📦 Processing dependencies...

──────────────────────────────────────── pip ───────────────────────────────────────────

Collecting pandas==2.1.4
  Downloading pandas-2.1.4-cp39-cp39-manylinux_2_17_x86_64.manylinux2014_x86_64.whl (12.3 MB)
     ━━━━━━━━━━━━━━━━━━━━━━━━━━━━━━━━━━━━━━━ 12.3/12.3 MB 197.3 MB/s eta 0:00:00[2024-02-10 22:19:04.470328] 
Collecting scikit-learn==1.3.2
  Downloading scikit_learn-1.3.2-cp39-cp39-manylinux_2_17_x86_64.manylinux2014_x86_64.whl (10.9 MB)
     ━━━━━━━━━━━━━━━━━━━━━━━━━━━━━━━━━━━━━━━ 10.9/10.9 MB 216.1 MB/s eta 0:00:00[2024-02-10 22:19:04.919922] 
Collecting streamlit==1.29.0
  Downloading streamlit-1.29.0-py2.py3-none-any.whl (8.4 MB)
     ━━━━━━━━━━━━━━━━━━━━━━━━━━━━━━━━━━━━━━━━ 8.4/8.4 MB 148.1 MB/s eta 0:00:00[2024-02-10 22:19:05.109595] 
Collecting matplotlib==3.8.2
  Downloading matplotlib-3.8.2-cp39-cp39-manylinux_2_17_x86_64.manylinux2014_x86_64.whl (11.6 MB)
     ━━━━━━━━━━━━━━━━━━━━━━━━━━━━━━━━━━━━━━━ 11.6/11.6 MB 177.9 MB/s eta 0:00:00[2024-02-10 22:19:05.553187] 
Collecting seaborn==0.13.1
  Downloading seaborn-0.13.1-py3-none-any.whl (294 kB)
     ━━━━━━━━━━━━━━━━━━━━━━━━━━━━━━━━━━━━━ 294.8/294.8 KB 263.0 MB/s eta 0:00:00[2024-02-10 22:19:05.615703] 
Collecting python-dateutil>=2.8.2
  Downloading python_dateutil-2.8.2-py2.py3-none-any.whl (247 kB)
     ━━━━━━━━━━━━━━━━━━━━━━━━━━━━━━━━━━━━━ 247.7/247.7 KB 258.3 MB/s eta 0:00:00[2024-02-10 22:19:05.746001] 
Collecting tzdata>=2022.1
  Downloading tzdata-2023.4-py2.py3-none-any.whl (346 kB)
     ━━━━━━━━━━━━━━━━━━━━━━━━━━━━━━━━━━━━━ 346.6/346.6 KB 180.7 MB/s eta 0:00:00[2024-02-10 22:19:05.808186] 
Collecting pytz>=2020.1
  Downloading pytz-2024.1-py2.py3-none-any.whl (505 kB)
     ━━━━━━━━━━━━━━━━━━━━━━━━━━━━━━━━━━━━━ 505.5/505.5 KB 173.8 MB/s eta 0:00:00[2024-02-10 22:19:05.942260] 
Collecting numpy<2,>=1.22.4
  Downloading numpy-1.26.4-cp39-cp39-manylinux_2_17_x86_64.manylinux2014_x86_64.whl (18.2 MB)
     ━━━━━━━━━━━━━━━━━━━━━━━━━━━━━━━━━━━━━━━ 18.2/18.2 MB 118.1 MB/s eta 0:00:00[2024-02-10 22:19:06.603072] 
Collecting scipy>=1.5.0
  Downloading scipy-1.12.0-cp39-cp39-manylinux_2_17_x86_64.manylinux2014_x86_64.whl (38.5 MB)
     ━━━━━━━━━━━━━━━━━━━━━━━━━━━━━━━━━━━━━━━ 38.5/38.5 MB 237.3 MB/s eta 0:00:00[2024-02-10 22:19:07.385930] 
Collecting threadpoolctl>=2.0.0
  Downloading threadpoolctl-3.2.0-py3-none-any.whl (15 kB)
Collecting joblib>=1.1.1
  Downloading joblib-1.3.2-py3-none-any.whl (302 kB)
     ━━━━━━━━━━━━━━━━━━━━━━━━━━━━━━━━━━━━━ 302.2/302.2 KB 262.5 MB/s eta 0:00:00[2024-02-10 22:19:07.543760] 
Collecting pydeck<1,>=0.8.0b4
  Downloading pydeck-0.8.1b0-py2.py3-none-any.whl (4.8 MB)
     ━━━━━━━━━━━━━━━━━━━━━━━━━━━━━━━━━━━━━━━━ 4.8/4.8 MB 145.3 MB/s eta 0:00:00[2024-02-10 22:19:07.674132] 
Collecting altair<6,>=4.0
  Downloading altair-5.2.0-py3-none-any.whl (996 kB)
     ━━━━━━━━━━━━━━━━━━━━━━━━━━━━━━━━━━━━━ 996.9/996.9 KB 147.6 MB/s eta 0:00:00[2024-02-10 22:19:07.763267] 
Collecting protobuf<5,>=3.20
  Downloading protobuf-4.25.2-cp37-abi3-manylinux2014_x86_64.whl (294 kB)
     ━━━━━━━━━━━━━━━━━━━━━━━━━━━━━━━━━━━━━ 294.6/294.6 KB 147.2 MB/s eta 0:00:00
Collecting validators<1,>=0.2
  Downloading validators-0.22.0-py3-none-any.whl (26 kB)
Collecting packaging<24,>=16.8
  Downloading packaging-23.2-py3-none-any.whl (53 kB)
     ━━━━━━━━━━━━━━━━━━━━━━━━━━━━━━━━━━━━━━━ 53.0/53.0 KB 158.7 MB/s eta 0:00:00[2024-02-10 22:19:08.597120] 
Collecting gitpython!=3.1.19,<4,>=3.0.7
  Downloading GitPython-3.1.41-py3-none-any.whl (196 kB)
     ━━━━━━━━━━━━━━━━━━━━━━━━━━━━━━━━━━━━━ 196.4/196.4 KB 148.6 MB/s eta 0:00:00[2024-02-10 22:19:08.711939] 
Collecting blinker<2,>=1.0.0
  Downloading blinker-1.7.0-py3-none-any.whl (13 kB)
Collecting pyarrow>=6.0
  Downloading pyarrow-15.0.0-cp39-cp39-manylinux_2_28_x86_64.whl (38.3 MB)
     ━━━━━━━━━━━━━━━━━━━━━━━━━━━━━━━━━━━━━━━ 38.3/38.3 MB 166.4 MB/s eta 0:00:00[2024-02-10 22:19:09.198691] 
Collecting cachetools<6,>=4.0
  Downloading cachetools-5.3.2-py3-none-any.whl (9.3 kB)
Collecting rich<14,>=10.14.0
  Downloading rich-13.7.0-py3-none-any.whl (240 kB)
     ━━━━━━━━━━━━━━━━━━━━━━━━━━━━━━━━━━━━━ 240.6/240.6 KB 212.6 MB/s eta 0:00:00[2024-02-10 22:19:09.448833] 
Collecting tornado<7,>=6.0.3
  Downloading tornado-6.4-cp38-abi3-manylinux_2_5_x86_64.manylinux1_x86_64.manylinux_2_17_x86_64.manylinux2014_x86_64.whl (435 kB)
     ━━━━━━━━━━━━━━━━━━━━━━━━━━━━━━━━━━━━━ 435.4/435.4 KB 206.1 MB/s eta 0:00:00[2024-02-10 22:19:09.566511] 
Collecting tenacity<9,>=8.1.0
  Downloading tenacity-8.2.3-py3-none-any.whl (24 kB)
Collecting importlib-metadata<7,>=1.4
  Downloading importlib_metadata-6.11.0-py3-none-any.whl (23 kB)
Collecting toml<2,>=0.10.1
  Downloading toml-0.10.2-py2.py3-none-any.whl (16 kB)
Collecting requests<3,>=2.27
  Downloading requests-2.31.0-py3-none-any.whl (62 kB)
     ━━━━━━━━━━━━━━━━━━━━━━━━━━━━━━━━━━━━━━━ 62.6/62.6 KB 130.9 MB/s eta 0:00:00[2024-02-10 22:19:09.960900] 
Collecting click<9,>=7.0
  Downloading click-8.1.7-py3-none-any.whl (97 kB)
     ━━━━━━━━━━━━━━━━━━━━━━━━━━━━━━━━━━━━━━━ 97.9/97.9 KB 239.5 MB/s eta 0:00:00[2024-02-10 22:19:10.057277] 
Collecting pillow<11,>=7.1.0
  Downloading pillow-10.2.0-cp39-cp39-manylinux_2_28_x86_64.whl (4.5 MB)
     ━━━━━━━━━━━━━━━━━━━━━━━━━━━━━━━━━━━━━━━━ 4.5/4.5 MB 142.7 MB/s eta 0:00:00[2024-02-10 22:19:10.672377] 
Collecting tzlocal<6,>=1.1
  Downloading tzlocal-5.2-py3-none-any.whl (17 kB)
Collecting watchdog>=2.1.5
  Downloading watchdog-4.0.0-py3-none-manylinux2014_x86_64.whl (82 kB)
     ━━━━━━━━━━━━━━━━━━━━━━━━━━━━━━━━━━━━━━━ 83.0/83.0 KB 108.6 MB/s eta 0:00:00[2024-02-10 22:19:10.946430] 
Collecting typing-extensions<5,>=4.3.0
  Downloading typing_extensions-4.9.0-py3-none-any.whl (32 kB)
Collecting kiwisolver>=1.3.1
  Downloading kiwisolver-1.4.5-cp39-cp39-manylinux_2_12_x86_64.manylinux2010_x86_64.whl (1.6 MB)
     ━━━━━━━━━━━━━━━━━━━━━━━━━━━━━━━━━━━━━━━━ 1.6/1.6 MB 139.2 MB/s eta 0:00:00[2024-02-10 22:19:11.164399] 
Collecting fonttools>=4.22.0
  Downloading fonttools-4.48.1-cp39-cp39-manylinux_2_17_x86_64.manylinux2014_x86_64.whl (4.6 MB)
     ━━━━━━━━━━━━━━━━━━━━━━━━━━━━━━━━━━━━━━━━ 4.6/4.6 MB 147.8 MB/s eta 0:00:00[2024-02-10 22:19:11.461623] 
Collecting contourpy>=1.0.1
  Downloading contourpy-1.2.0-cp39-cp39-manylinux_2_17_x86_64.manylinux2014_x86_64.whl (310 kB)
     ━━━━━━━━━━━━━━━━━━━━━━━━━━━━━━━━━━━━━ 311.0/311.0 KB 191.3 MB/s eta 0:00:00[2024-02-10 22:19:11.768313] 
Collecting importlib-resources>=3.2.0
  Downloading importlib_resources-6.1.1-py3-none-any.whl (33 kB)
Collecting cycler>=0.10
  Downloading cycler-0.12.1-py3-none-any.whl (8.3 kB)
Collecting pyparsing>=2.3.1
  Downloading pyparsing-3.1.1-py3-none-any.whl (103 kB)
     ━━━━━━━━━━━━━━━━━━━━━━━━━━━━━━━━━━━━━ 103.1/103.1 KB 142.0 MB/s eta 0:00:00[2024-02-10 22:19:12.001549] 
Collecting jsonschema>=3.0
  Downloading jsonschema-4.21.1-py3-none-any.whl (85 kB)
     ━━━━━━━━━━━━━━━━━━━━━━━━━━━━━━━━━━━━━━━ 85.5/85.5 KB 130.7 MB/s eta 0:00:00[2024-02-10 22:19:12.256271] 
Collecting toolz
  Downloading toolz-0.12.1-py3-none-any.whl (56 kB)
     ━━━━━━━━━━━━━━━━━━━━━━━━━━━━━━━━━━━━━━━ 56.1/56.1 KB 197.9 MB/s eta 0:00:00[2024-02-10 22:19:12.302260] 
Collecting jinja2
  Downloading Jinja2-3.1.3-py3-none-any.whl (133 kB)
     ━━━━━━━━━━━━━━━━━━━━━━━━━━━━━━━━━━━━━ 133.2/133.2 KB 192.9 MB/s eta 0:00:00[2024-02-10 22:19:12.367068] 
Collecting gitdb<5,>=4.0.1
  Downloading gitdb-4.0.11-py3-none-any.whl (62 kB)
     ━━━━━━━━━━━━━━━━━━━━━━━━━━━━━━━━━━━━━━━ 62.7/62.7 KB 155.2 MB/s eta 0:00:00[2024-02-10 22:19:12.504332] 
Collecting zipp>=0.5
  Downloading zipp-3.17.0-py3-none-any.whl (7.4 kB)
Collecting six>=1.5
  Downloading six-1.16.0-py2.py3-none-any.whl (11 kB)
Collecting charset-normalizer<4,>=2
  Downloading charset_normalizer-3.3.2-cp39-cp39-manylinux_2_17_x86_64.manylinux2014_x86_64.whl (142 kB)
     ━━━━━━━━━━━━━━━━━━━━━━━━━━━━━━━━━━━━━ 142.3/142.3 KB 190.2 MB/s eta 0:00:00[2024-02-10 22:19:13.162723] 
Collecting urllib3<3,>=1.21.1
  Downloading urllib3-2.2.0-py3-none-any.whl (120 kB)
     ━━━━━━━━━━━━━━━━━━━━━━━━━━━━━━━━━━━━━ 120.9/120.9 KB 135.7 MB/s eta 0:00:00[2024-02-10 22:19:13.285730] 
Collecting idna<4,>=2.5
  Downloading idna-3.6-py3-none-any.whl (61 kB)
     ━━━━━━━━━━━━━━━━━━━━━━━━━━━━━━━━━━━━━━━ 61.6/61.6 KB 120.3 MB/s eta 0:00:00[2024-02-10 22:19:13.335005] 
Collecting certifi>=2017.4.17
  Downloading certifi-2024.2.2-py3-none-any.whl (163 kB)
     ━━━━━━━━━━━━━━━━━━━━━━━━━━━━━━━━━━━━━ 163.8/163.8 KB 130.2 MB/s eta 0:00:00
Collecting pygments<3.0.0,>=2.13.0
  Downloading pygments-2.17.2-py3-none-any.whl (1.2 MB)
     ━━━━━━━━━━━━━━━━━━━━━━━━━━━━━━━━━━━━━━━━ 1.2/1.2 MB 143.6 MB/s eta 0:00:00[2024-02-10 22:19:13.531327] 
Collecting markdown-it-py>=2.2.0
  Downloading markdown_it_py-3.0.0-py3-none-any.whl (87 kB)
     ━━━━━━━━━━━━━━━━━━━━━━━━━━━━━━━━━━━━━━━ 87.5/87.5 KB 137.3 MB/s eta 0:00:00[2024-02-10 22:19:13.617991] 
Collecting smmap<6,>=3.0.1
  Downloading smmap-5.0.1-py3-none-any.whl (24 kB)
Collecting MarkupSafe>=2.0
  Downloading MarkupSafe-2.1.5-cp39-cp39-manylinux_2_17_x86_64.manylinux2014_x86_64.whl (25 kB)
Collecting attrs>=22.2.0
  Downloading attrs-23.2.0-py3-none-any.whl (60 kB)
     ━━━━━━━━━━━━━━━━━━━━━━━━━━━━━━━━━━━━━━━ 60.8/60.8 KB 163.9 MB/s eta 0:00:00[2024-02-10 22:19:14.076787] 
Collecting referencing>=0.28.4
  Downloading referencing-0.33.0-py3-none-any.whl (26 kB)
Collecting rpds-py>=0.7.1
  Downloading rpds_py-0.17.1-cp39-cp39-manylinux_2_17_x86_64.manylinux2014_x86_64.whl (1.2 MB)
     ━━━━━━━━━━━━━━━━━━━━━━━━━━━━━━━━━━━━━━━━ 1.2/1.2 MB 188.2 MB/s eta 0:00:00[2024-02-10 22:19:14.861655] 
Collecting jsonschema-specifications>=2023.03.6
  Downloading jsonschema_specifications-2023.12.1-py3-none-any.whl (18 kB)
Collecting mdurl~=0.1
  Downloading mdurl-0.1.2-py3-none-any.whl (10.0 kB)
Installing collected packages: pytz, zipp, watchdog, validators, urllib3, tzlocal, tzdata, typing-extensions, tornado, toolz, toml, threadpoolctl, tenacity, smmap, six, rpds-py, pyparsing, pygments, protobuf, pillow, packaging, numpy, mdurl, MarkupSafe, kiwisolver, joblib, idna, fonttools, cycler, click, charset-normalizer, certifi, cachetools, blinker, attrs, scipy, requests, referencing, python-dateutil, pyarrow, markdown-it-py, jinja2, importlib-resources, importlib-metadata, gitdb, contourpy, scikit-learn, rich, pydeck, pandas, matplotlib, jsonschema-specifications, gitpython, seaborn, jsonschema, altair, streamlit
Successfully installed MarkupSafe-2.1.5 altair-5.2.0 attrs-23.2.0 blinker-1.7.0 cachetools-5.3.2 certifi-2024.2.2 charset-normalizer-3.3.2 click-8.1.7 contourpy-1.2.0 cycler-0.12.1 fonttools-4.48.1 gitdb-4.0.11 gitpython-3.1.41 idna-3.6 importlib-metadata-6.11.0 importlib-resources-6.1.1 jinja2-3.1.3 joblib-1.3.2 jsonschema-4.21.1 jsonschema-specifications-2023.12.1 kiwisolver-1.4.5 markdown-it-py-3.0.0 matplotlib-3.8.2 mdurl-0.1.2 numpy-1.26.4 packaging-23.2 pandas-2.1.4 pillow-10.2.0 protobuf-4.25.2 pyarrow-15.0.0 pydeck-0.8.1b0 pygments-2.17.2 pyparsing-3.1.1 python-dateutil-2.8.2 pytz-2024.1 referencing-0.33.0 requests-2.31.0 rich-13.7.0 rpds-py-0.17.1 scikit-learn-1.3.2 scipy-1.12.0 seaborn-0.13.1 six-1.16.0 smmap-5.0.1 streamlit-1.29.0 tenacity-8.2.3 threadpoolctl-3.2.0 toml-0.10.2 toolz-0.12.1 tornado-6.4 typing-extensions-4.9.0 tzdata-2023.4 tzlocal-5.2 urllib3-2.2.0 validators-0.22.0 watchdog-4.0.0 zipp-3.17.0
WARNING: You are using pip version 22.0.3; however, version 24.0 is available.
You should consider upgrading via the '/home/adminuser/venv/bin/python -m pip install --upgrade pip' command.
Checking if Streamlit is installed
Found Streamlit version 1.29.0 in the environment

────────────────────────────────────────────────────────────────────────────────────────

[22:19:44] 🐍 Python dependencies were installed from /mount/src/cardioriskanalyzer/requirements.txt using pip.
Check if streamlit is installed
Streamlit is already installed
[22:19:45] 📦 Processed dependencies!



2024-02-10 22:19:53.948 Uncaught app exception
Traceback (most recent call last):
  File "/home/adminuser/venv/lib/python3.9/site-packages/streamlit/runtime/scriptrunner/script_runner.py", line 534, in _run_script
    exec(code, module.__dict__)
  File "/mount/src/cardioriskanalyzer/scripts/heart_disease_prediction.py", line 16, in <module>
    random_forest = joblib.load(model_file_path)
  File "/home/adminuser/venv/lib/python3.9/site-packages/joblib/numpy_pickle.py", line 650, in load
    with open(filename, 'rb') as f:
FileNotFoundError: [Errno 2] No such file or directory: 'D:/MPS Analytics/CardioRiskAnalyzer/models/random_forest_model.pkl'
[22:19:54] ❗️ 
2024-02-10 22:19:54.002 503 GET /script-health-check (10.12.118.41) 104.47ms
2024-02-10 22:19:58.877 Uncaught app exception
Traceback (most recent call last):
  File "/home/adminuser/venv/lib/python3.9/site-packages/streamlit/runtime/scriptrunner/script_runner.py", line 534, in _run_script
    exec(code, module.__dict__)
  File "/mount/src/cardioriskanalyzer/scripts/heart_disease_prediction.py", line 16, in <module>
    random_forest = joblib.load(model_file_path)
  File "/home/adminuser/venv/lib/python3.9/site-packages/joblib/numpy_pickle.py", line 650, in load
    with open(filename, 'rb') as f:
FileNotFoundError: [Errno 2] No such file or directory: 'D:/MPS Analytics/CardioRiskAnalyzer/models/random_forest_model.pkl'
2024-02-10 22:19:58.878 503 GET /script-health-check (10.12.118.41) 2.57ms
2024-02-10 22:20:02.646 Uncaught app exception
Traceback (most recent call last):
  File "/home/adminuser/venv/lib/python3.9/site-packages/streamlit/runtime/scriptrunner/script_runner.py", line 534, in _run_script
    exec(code, module.__dict__)
  File "/mount/src/cardioriskanalyzer/scripts/heart_disease_prediction.py", line 16, in <module>
    random_forest = joblib.load(model_file_path)
  File "/home/adminuser/venv/lib/python3.9/site-packages/joblib/numpy_pickle.py", line 650, in load
    with open(filename, 'rb') as f:
FileNotFoundError: [Errno 2] No such file or directory: 'D:/MPS Analytics/CardioRiskAnalyzer/models/random_forest_model.pkl'
2024-02-10 22:20:03.915 Uncaught app exception
Traceback (most recent call last):
  File "/home/adminuser/venv/lib/python3.9/site-packages/streamlit/runtime/scriptrunner/script_runner.py", line 534, in _run_script
    exec(code, module.__dict__)
  File "/mount/src/cardioriskanalyzer/scripts/heart_disease_prediction.py", line 16, in <module>
    random_forest = joblib.load(model_file_path)
  File "/home/adminuser/venv/lib/python3.9/site-packages/joblib/numpy_pickle.py", line 650, in load
    with open(filename, 'rb') as f:
FileNotFoundError: [Errno 2] No such file or directory: 'D:/MPS Analytics/CardioRiskAnalyzer/models/random_forest_model.pkl'
2024-02-10 22:20:04.037 503 GET /script-health-check (10.12.118.41) 124.04ms
2024-02-10 22:20:08.871 Uncaught app exception
Traceback (most recent call last):
  File "/home/adminuser/venv/lib/python3.9/site-packages/streamlit/runtime/scriptrunner/script_runner.py", line 534, in _run_script
    exec(code, module.__dict__)
  File "/mount/src/cardioriskanalyzer/scripts/heart_disease_prediction.py", line 16, in <module>
    random_forest = joblib.load(model_file_path)
  File "/home/adminuser/venv/lib/python3.9/site-packages/joblib/numpy_pickle.py", line 650, in load
    with open(filename, 'rb') as f:
FileNotFoundError: [Errno 2] No such file or directory: 'D:/MPS Analytics/CardioRiskAnalyzer/models/random_forest_model.pkl'
2024-02-10 22:20:09.051 503 GET /script-health-check (10.12.118.41) 181.98ms
2024-02-10 22:20:13.857 Uncaught app exception
Traceback (most recent call last):
  File "/home/adminuser/venv/lib/python3.9/site-packages/streamlit/runtime/scriptrunner/script_runner.py", line 534, in _run_script
    exec(code, module.__dict__)
  File "/mount/src/cardioriskanalyzer/scripts/heart_disease_prediction.py", line 16, in <module>
    random_forest = joblib.load(model_file_path)
  File "/home/adminuser/venv/lib/python3.9/site-packages/joblib/numpy_pickle.py", line 650, in load
    with open(filename, 'rb') as f:
FileNotFoundError: [Errno 2] No such file or directory: 'D:/MPS Analytics/CardioRiskAnalyzer/models/random_forest_model.pkl'
2024-02-10 22:20:14.039 503 GET /script-health-check (10.12.118.41) 183.55ms
2024-02-10 22:20:18.974 Uncaught app exception
Traceback (most recent call last):
  File "/home/adminuser/venv/lib/python3.9/site-packages/streamlit/runtime/scriptrunner/script_runner.py", line 534, in _run_script
    exec(code, module.__dict__)
  File "/mount/src/cardioriskanalyzer/scripts/heart_disease_prediction.py", line 16, in <module>
    random_forest = joblib.load(model_file_path)
  File "/home/adminuser/venv/lib/python3.9/site-packages/joblib/numpy_pickle.py", line 650, in load
    with open(filename, 'rb') as f:
FileNotFoundError: [Errno 2] No such file or directory: 'D:/MPS Analytics/CardioRiskAnalyzer/models/random_forest_model.pkl'
2024-02-10 22:20:19.104 503 GET /script-health-check (10.12.118.41) 132.08ms
2024-02-10 22:20:23.906 Uncaught app exception
Traceback (most recent call last):
  File "/home/adminuser/venv/lib/python3.9/site-packages/streamlit/runtime/scriptrunner/script_runner.py", line 534, in _run_script
    exec(code, module.__dict__)
  File "/mount/src/cardioriskanalyzer/scripts/heart_disease_prediction.py", line 16, in <module>
    random_forest = joblib.load(model_file_path)
  File "/home/adminuser/venv/lib/python3.9/site-packages/joblib/numpy_pickle.py", line 650, in load
    with open(filename, 'rb') as f:
FileNotFoundError: [Errno 2] No such file or directory: 'D:/MPS Analytics/CardioRiskAnalyzer/models/random_forest_model.pkl'
2024-02-10 22:20:23.907 503 GET /script-health-check (10.12.118.41) 2.07ms
2024-02-10 22:20:28.869 Uncaught app exception
Traceback (most recent call last):
  File "/home/adminuser/venv/lib/python3.9/site-packages/streamlit/runtime/scriptrunner/script_runner.py", line 534, in _run_script
    exec(code, module.__dict__)
  File "/mount/src/cardioriskanalyzer/scripts/heart_disease_prediction.py", line 16, in <module>
    random_forest = joblib.load(model_file_path)
  File "/home/adminuser/venv/lib/python3.9/site-packages/joblib/numpy_pickle.py", line 650, in load
    with open(filename, 'rb') as f:
FileNotFoundError: [Errno 2] No such file or directory: 'D:/MPS Analytics/CardioRiskAnalyzer/models/random_forest_model.pkl'
2024-02-10 22:20:28.982 503 GET /script-health-check (10.12.118.41) 114.96ms
2024-02-10 22:20:33.898 503 GET /script-health-check (10.12.118.41) 2.04ms
2024-02-10 22:20:33.897 Uncaught app exception
Traceback (most recent call last):
  File "/home/adminuser/venv/lib/python3.9/site-packages/streamlit/runtime/scriptrunner/script_runner.py", line 534, in _run_script
    exec(code, module.__dict__)
  File "/mount/src/cardioriskanalyzer/scripts/heart_disease_prediction.py", line 16, in <module>
    random_forest = joblib.load(model_file_path)
  File "/home/adminuser/venv/lib/python3.9/site-packages/joblib/numpy_pickle.py", line 650, in load
    with open(filename, 'rb') as f:
FileNotFoundError: [Errno 2] No such file or directory: 'D:/MPS Analytics/CardioRiskAnalyzer/models/random_forest_model.pkl'
2024-02-10 22:20:38.833 503 GET /script-health-check (10.12.118.41) 2.07ms
2024-02-10 22:20:38.833 Uncaught app exception
Traceback (most recent call last):
  File "/home/adminuser/venv/lib/python3.9/site-packages/streamlit/runtime/scriptrunner/script_runner.py", line 534, in _run_script
    exec(code, module.__dict__)
  File "/mount/src/cardioriskanalyzer/scripts/heart_disease_prediction.py", line 16, in <module>
    random_forest = joblib.load(model_file_path)
  File "/home/adminuser/venv/lib/python3.9/site-packages/joblib/numpy_pickle.py", line 650, in load
    with open(filename, 'rb') as f:
FileNotFoundError: [Errno 2] No such file or directory: 'D:/MPS Analytics/CardioRiskAnalyzer/models/random_forest_model.pkl'
2024-02-10 22:20:43.902 Uncaught app exception
Traceback (most recent call last):
  File "/home/adminuser/venv/lib/python3.9/site-packages/streamlit/runtime/scriptrunner/script_runner.py", line 534, in _run_script
    exec(code, module.__dict__)
  File "/mount/src/cardioriskanalyzer/scripts/heart_disease_prediction.py", line 16, in <module>
    random_forest = joblib.load(model_file_path)
  File "/home/adminuser/venv/lib/python3.9/site-packages/joblib/numpy_pickle.py", line 650, in load
    with open(filename, 'rb') as f:
FileNotFoundError: [Errno 2] No such file or directory: 'D:/MPS Analytics/CardioRiskAnalyzer/models/random_forest_model.pkl'
2024-02-10 22:20:43.954 503 GET /script-health-check (10.12.118.41) 53.75ms
2024-02-10 22:20:48.883 503 GET /script-health-check (10.12.118.41) 1.58ms
2024-02-10 22:20:48.882 Uncaught app exception
Traceback (most recent call last):
  File "/home/adminuser/venv/lib/python3.9/site-packages/streamlit/runtime/scriptrunner/script_runner.py", line 534, in _run_script
    exec(code, module.__dict__)
  File "/mount/src/cardioriskanalyzer/scripts/heart_disease_prediction.py", line 16, in <module>
    random_forest = joblib.load(model_file_path)
  File "/home/adminuser/venv/lib/python3.9/site-packages/joblib/numpy_pickle.py", line 650, in load
    with open(filename, 'rb') as f:
FileNotFoundError: [Errno 2] No such file or directory: 'D:/MPS Analytics/CardioRiskAnalyzer/models/random_forest_model.pkl'
2024-02-10 22:20:53.855 Uncaught app exception
Traceback (most recent call last):
  File "/home/adminuser/venv/lib/python3.9/site-packages/streamlit/runtime/scriptrunner/script_runner.py", line 534, in _run_script
    exec(code, module.__dict__)
  File "/mount/src/cardioriskanalyzer/scripts/heart_disease_prediction.py", line 16, in <module>
    random_forest = joblib.load(model_file_path)
  File "/home/adminuser/venv/lib/python3.9/site-packages/joblib/numpy_pickle.py", line 650, in load
    with open(filename, 'rb') as f:
FileNotFoundError: [Errno 2] No such file or directory: 'D:/MPS Analytics/CardioRiskAnalyzer/models/random_forest_model.pkl'
2024-02-10 22:20:53.996 503 GET /script-health-check (10.12.118.41) 142.29ms
2024-02-10 22:20:58.934 503 GET /script-health-check (10.12.118.41) 2.40ms
2024-02-10 22:20:58.933 Uncaught app exception
Traceback (most recent call last):
  File "/home/adminuser/venv/lib/python3.9/site-packages/streamlit/runtime/scriptrunner/script_runner.py", line 534, in _run_script
    exec(code, module.__dict__)
  File "/mount/src/cardioriskanalyzer/scripts/heart_disease_prediction.py", line 16, in <module>
    random_forest = joblib.load(model_file_path)
  File "/home/adminuser/venv/lib/python3.9/site-packages/joblib/numpy_pickle.py", line 650, in load
    with open(filename, 'rb') as f:
FileNotFoundError: [Errno 2] No such file or directory: 'D:/MPS Analytics/CardioRiskAnalyzer/models/random_forest_model.pkl'
2024-02-10 22:21:03.854 Uncaught app exception
Traceback (most recent call last):
  File "/home/adminuser/venv/lib/python3.9/site-packages/streamlit/runtime/scriptrunner/script_runner.py", line 534, in _run_script
    exec(code, module.__dict__)
  File "/mount/src/cardioriskanalyzer/scripts/heart_disease_prediction.py", line 16, in <module>
    random_forest = joblib.load(model_file_path)
  File "/home/adminuser/venv/lib/python3.9/site-packages/joblib/numpy_pickle.py", line 650, in load
    with open(filename, 'rb') as f:
FileNotFoundError: [Errno 2] No such file or directory: 'D:/MPS Analytics/CardioRiskAnalyzer/models/random_forest_model.pkl'
2024-02-10 22:21:04.050 503 GET /script-health-check (10.12.118.41) 197.57ms
2024-02-10 22:21:08.866 503 GET /script-health-check (10.12.118.41) 2.00ms
2024-02-10 22:21:08.866 Uncaught app exception
Traceback (most recent call last):
  File "/home/adminuser/venv/lib/python3.9/site-packages/streamlit/runtime/scriptrunner/script_runner.py", line 534, in _run_script
    exec(code, module.__dict__)
  File "/mount/src/cardioriskanalyzer/scripts/heart_disease_prediction.py", line 16, in <module>
    random_forest = joblib.load(model_file_path)
  File "/home/adminuser/venv/lib/python3.9/site-packages/joblib/numpy_pickle.py", line 650, in load
    with open(filename, 'rb') as f:
FileNotFoundError: [Errno 2] No such file or directory: 'D:/MPS Analytics/CardioRiskAnalyzer/models/random_forest_model.pkl'
2024-02-10 22:21:13.960 Uncaught app exception
Traceback (most recent call last):
  File "/home/adminuser/venv/lib/python3.9/site-packages/streamlit/runtime/scriptrunner/script_runner.py", line 534, in _run_script
    exec(code, module.__dict__)
  File "/mount/src/cardioriskanalyzer/scripts/heart_disease_prediction.py", line 16, in <module>
    random_forest = joblib.load(model_file_path)
  File "/home/adminuser/venv/lib/python3.9/site-packages/joblib/numpy_pickle.py", line 650, in load
    with open(filename, 'rb') as f:
FileNotFoundError: [Errno 2] No such file or directory: 'D:/MPS Analytics/CardioRiskAnalyzer/models/random_forest_model.pkl'
2024-02-10 22:21:14.089 503 GET /script-health-check (10.12.118.41) 131.13ms
2024-02-10 22:21:18.873 Uncaught app exception
Traceback (most recent call last):
  File "/home/adminuser/venv/lib/python3.9/site-packages/streamlit/runtime/scriptrunner/script_runner.py", line 534, in _run_script
    exec(code, module.__dict__)
  File "/mount/src/cardioriskanalyzer/scripts/heart_disease_prediction.py", line 16, in <module>
    random_forest = joblib.load(model_file_path)
  File "/home/adminuser/venv/lib/python3.9/site-packages/joblib/numpy_pickle.py", line 650, in load
    with open(filename, 'rb') as f:
FileNotFoundError: [Errno 2] No such file or directory: 'D:/MPS Analytics/CardioRiskAnalyzer/models/random_forest_model.pkl'
2024-02-10 22:21:19.062 503 GET /script-health-check (10.12.118.41) 190.17ms
2024-02-10 22:21:23.893 Uncaught app exception
Traceback (most recent call last):
  File "/home/adminuser/venv/lib/python3.9/site-packages/streamlit/runtime/scriptrunner/script_runner.py", line 534, in _run_script
    exec(code, module.__dict__)
  File "/mount/src/cardioriskanalyzer/scripts/heart_disease_prediction.py", line 16, in <module>
    random_forest = joblib.load(model_file_path)
  File "/home/adminuser/venv/lib/python3.9/site-packages/joblib/numpy_pickle.py", line 650, in load
    with open(filename, 'rb') as f:
FileNotFoundError: [Errno 2] No such file or directory: 'D:/MPS Analytics/CardioRiskAnalyzer/models/random_forest_model.pkl'
2024-02-10 22:21:24.079 503 GET /script-health-check (10.12.118.41) 188.15ms
2024-02-10 22:21:28.842 Uncaught app exception
Traceback (most recent call last):
  File "/home/adminuser/venv/lib/python3.9/site-packages/streamlit/runtime/scriptrunner/script_runner.py", line 534, in _run_script
    exec(code, module.__dict__)
  File "/mount/src/cardioriskanalyzer/scripts/heart_disease_prediction.py", line 16, in <module>
    random_forest = joblib.load(model_file_path)
  File "/home/adminuser/venv/lib/python3.9/site-packages/joblib/numpy_pickle.py", line 650, in load
    with open(filename, 'rb') as f:
FileNotFoundError: [Errno 2] No such file or directory: 'D:/MPS Analytics/CardioRiskAnalyzer/models/random_forest_model.pkl'
2024-02-10 22:21:28.968 503 GET /script-health-check (10.12.118.41) 127.34ms
2024-02-10 22:21:33.944 Uncaught app exception
Traceback (most recent call last):
  File "/home/adminuser/venv/lib/python3.9/site-packages/streamlit/runtime/scriptrunner/script_runner.py", line 534, in _run_script
    exec(code, module.__dict__)
  File "/mount/src/cardioriskanalyzer/scripts/heart_disease_prediction.py", line 16, in <module>
    random_forest = joblib.load(model_file_path)
  File "/home/adminuser/venv/lib/python3.9/site-packages/joblib/numpy_pickle.py", line 650, in load
    with open(filename, 'rb') as f:
FileNotFoundError: [Errno 2] No such file or directory: 'D:/MPS Analytics/CardioRiskAnalyzer/models/random_forest_model.pkl'
2024-02-10 22:21:34.061 503 GET /script-health-check (10.12.118.41) 118.46ms
2024-02-10 22:21:38.881 Uncaught app exception
Traceback (most recent call last):
  File "/home/adminuser/venv/lib/python3.9/site-packages/streamlit/runtime/scriptrunner/script_runner.py", line 534, in _run_script
    exec(code, module.__dict__)
  File "/mount/src/cardioriskanalyzer/scripts/heart_disease_prediction.py", line 16, in <module>
    random_forest = joblib.load(model_file_path)
  File "/home/adminuser/venv/lib/python3.9/site-packages/joblib/numpy_pickle.py", line 650, in load
    with open(filename, 'rb') as f:
FileNotFoundError: [Errno 2] No such file or directory: 'D:/MPS Analytics/CardioRiskAnalyzer/models/random_forest_model.pkl'
2024-02-10 22:21:39.001 503 GET /script-health-check (10.12.118.41) 121.91ms
2024-02-10 22:21:43.873 Uncaught app exception
Traceback (most recent call last):
  File "/home/adminuser/venv/lib/python3.9/site-packages/streamlit/runtime/scriptrunner/script_runner.py", line 534, in _run_script
    exec(code, module.__dict__)
  File "/mount/src/cardioriskanalyzer/scripts/heart_disease_prediction.py", line 16, in <module>
    random_forest = joblib.load(model_file_path)
  File "/home/adminuser/venv/lib/python3.9/site-packages/joblib/numpy_pickle.py", line 650, in load
    with open(filename, 'rb') as f:
FileNotFoundError: [Errno 2] No such file or directory: 'D:/MPS Analytics/CardioRiskAnalyzer/models/random_forest_model.pkl'
2024-02-10 22:21:44.037 503 GET /script-health-check (10.12.118.41) 166.06ms
2024-02-10 22:21:48.914 Uncaught app exception
Traceback (most recent call last):
  File "/home/adminuser/venv/lib/python3.9/site-packages/streamlit/runtime/scriptrunner/script_runner.py", line 534, in _run_script
    exec(code, module.__dict__)
  File "/mount/src/cardioriskanalyzer/scripts/heart_disease_prediction.py", line 16, in <module>
    random_forest = joblib.load(model_file_path)
  File "/home/adminuser/venv/lib/python3.9/site-packages/joblib/numpy_pickle.py", line 650, in load
    with open(filename, 'rb') as f:
FileNotFoundError: [Errno 2] No such file or directory: 'D:/MPS Analytics/CardioRiskAnalyzer/models/random_forest_model.pkl'
2024-02-10 22:21:49.035 503 GET /script-health-check (10.12.118.41) 122.68ms
2024-02-10 22:21:53.914 Uncaught app exception
Traceback (most recent call last):
  File "/home/adminuser/venv/lib/python3.9/site-packages/streamlit/runtime/scriptrunner/script_runner.py", line 534, in _run_script
    exec(code, module.__dict__)
  File "/mount/src/cardioriskanalyzer/scripts/heart_disease_prediction.py", line 16, in <module>
    random_forest = joblib.load(model_file_path)
  File "/home/adminuser/venv/lib/python3.9/site-packages/joblib/numpy_pickle.py", line 650, in load
    with open(filename, 'rb') as f:
FileNotFoundError: [Errno 2] No such file or directory: 'D:/MPS Analytics/CardioRiskAnalyzer/models/random_forest_model.pkl'
2024-02-10 22:21:54.081 503 GET /script-health-check (10.12.118.41) 169.43ms
2024-02-10 22:21:58.937 503 GET /script-health-check (10.12.118.41) 2.24ms
2024-02-10 22:21:58.937 Uncaught app exception
Traceback (most recent call last):
  File "/home/adminuser/venv/lib/python3.9/site-packages/streamlit/runtime/scriptrunner/script_runner.py", line 534, in _run_script
    exec(code, module.__dict__)
  File "/mount/src/cardioriskanalyzer/scripts/heart_disease_prediction.py", line 16, in <module>
    random_forest = joblib.load(model_file_path)
  File "/home/adminuser/venv/lib/python3.9/site-packages/joblib/numpy_pickle.py", line 650, in load
    with open(filename, 'rb') as f:
FileNotFoundError: [Errno 2] No such file or directory: 'D:/MPS Analytics/CardioRiskAnalyzer/models/random_forest_model.pkl'
2024-02-10 22:22:03.853 Uncaught app exception
Traceback (most recent call last):
  File "/home/adminuser/venv/lib/python3.9/site-packages/streamlit/runtime/scriptrunner/script_runner.py", line 534, in _run_script
    exec(code, module.__dict__)
  File "/mount/src/cardioriskanalyzer/scripts/heart_disease_prediction.py", line 16, in <module>
    random_forest = joblib.load(model_file_path)
  File "/home/adminuser/venv/lib/python3.9/site-packages/joblib/numpy_pickle.py", line 650, in load
    with open(filename, 'rb') as f:
FileNotFoundError: [Errno 2] No such file or directory: 'D:/MPS Analytics/CardioRiskAnalyzer/models/random_forest_model.pkl'
2024-02-10 22:22:03.969 503 GET /script-health-check (10.12.118.41) 117.94ms
2024-02-10 22:22:08.873 Uncaught app exception
Traceback (most recent call last):
  File "/home/adminuser/venv/lib/python3.9/site-packages/streamlit/runtime/scriptrunner/script_runner.py", line 534, in _run_script
    exec(code, module.__dict__)
  File "/mount/src/cardioriskanalyzer/scripts/heart_disease_prediction.py", line 16, in <module>
    random_forest = joblib.load(model_file_path)
  File "/home/adminuser/venv/lib/python3.9/site-packages/joblib/numpy_pickle.py", line 650, in load
    with open(filename, 'rb') as f:
FileNotFoundError: [Errno 2] No such file or directory: 'D:/MPS Analytics/CardioRiskAnalyzer/models/random_forest_model.pkl'
2024-02-10 22:22:09.042 503 GET /script-health-check (10.12.118.41) 170.87ms
2024-02-10 22:22:13.872 Uncaught app exception
Traceback (most recent call last):
  File "/home/adminuser/venv/lib/python3.9/site-packages/streamlit/runtime/scriptrunner/script_runner.py", line 534, in _run_script
    exec(code, module.__dict__)
  File "/mount/src/cardioriskanalyzer/scripts/heart_disease_prediction.py", line 16, in <module>
    random_forest = joblib.load(model_file_path)
  File "/home/adminuser/venv/lib/python3.9/site-packages/joblib/numpy_pickle.py", line 650, in load
    with open(filename, 'rb') as f:
FileNotFoundError: [Errno 2] No such file or directory: 'D:/MPS Analytics/CardioRiskAnalyzer/models/random_forest_model.pkl'
2024-02-10 22:22:13.990 503 GET /script-health-check (10.12.118.41) 120.49ms
2024-02-10 22:22:18.871 Uncaught app exception
Traceback (most recent call last):
  File "/home/adminuser/venv/lib/python3.9/site-packages/streamlit/runtime/scriptrunner/script_runner.py", line 534, in _run_script
    exec(code, module.__dict__)
  File "/mount/src/cardioriskanalyzer/scripts/heart_disease_prediction.py", line 16, in <module>
    random_forest = joblib.load(model_file_path)
  File "/home/adminuser/venv/lib/python3.9/site-packages/joblib/numpy_pickle.py", line 650, in load
    with open(filename, 'rb') as f:
FileNotFoundError: [Errno 2] No such file or directory: 'D:/MPS Analytics/CardioRiskAnalyzer/models/random_forest_model.pkl'
2024-02-10 22:22:18.992 503 GET /script-health-check (10.12.118.41) 122.77ms
2024-02-10 22:22:23.888 Uncaught app exception
Traceback (most recent call last):
  File "/home/adminuser/venv/lib/python3.9/site-packages/streamlit/runtime/scriptrunner/script_runner.py", line 534, in _run_script
    exec(code, module.__dict__)
  File "/mount/src/cardioriskanalyzer/scripts/heart_disease_prediction.py", line 16, in <module>
    random_forest = joblib.load(model_file_path)
  File "/home/adminuser/venv/lib/python3.9/site-packages/joblib/numpy_pickle.py", line 650, in load
    with open(filename, 'rb') as f:
FileNotFoundError: [Errno 2] No such file or directory: 'D:/MPS Analytics/CardioRiskAnalyzer/models/random_forest_model.pkl'
2024-02-10 22:22:23.931 503 GET /script-health-check (10.12.118.41) 45.15ms
2024-02-10 22:22:28.958 Uncaught app exception
Traceback (most recent call last):
  File "/home/adminuser/venv/lib/python3.9/site-packages/streamlit/runtime/scriptrunner/script_runner.py", line 534, in _run_script
    exec(code, module.__dict__)
  File "/mount/src/cardioriskanalyzer/scripts/heart_disease_prediction.py", line 16, in <module>
    random_forest = joblib.load(model_file_path)
  File "/home/adminuser/venv/lib/python3.9/site-packages/joblib/numpy_pickle.py", line 650, in load
    with open(filename, 'rb') as f:
FileNotFoundError: [Errno 2] No such file or directory: 'D:/MPS Analytics/CardioRiskAnalyzer/models/random_forest_model.pkl'
2024-02-10 22:22:29.127 503 GET /script-health-check (10.12.118.41) 171.27ms
2024-02-10 22:22:33.959 Uncaught app exception
Traceback (most recent call last):
  File "/home/adminuser/venv/lib/python3.9/site-packages/streamlit/runtime/scriptrunner/script_runner.py", line 534, in _run_script
    exec(code, module.__dict__)
  File "/mount/src/cardioriskanalyzer/scripts/heart_disease_prediction.py", line 16, in <module>
    random_forest = joblib.load(model_file_path)
  File "/home/adminuser/venv/lib/python3.9/site-packages/joblib/numpy_pickle.py", line 650, in load
    with open(filename, 'rb') as f:
FileNotFoundError: [Errno 2] No such file or directory: 'D:/MPS Analytics/CardioRiskAnalyzer/models/random_forest_model.pkl'
2024-02-10 22:22:34.080 503 GET /script-health-check (10.12.118.41) 121.96ms
2024-02-10 22:22:38.964 Uncaught app exception
Traceback (most recent call last):
  File "/home/adminuser/venv/lib/python3.9/site-packages/streamlit/runtime/scriptrunner/script_runner.py", line 534, in _run_script
    exec(code, module.__dict__)
  File "/mount/src/cardioriskanalyzer/scripts/heart_disease_prediction.py", line 16, in <module>
    random_forest = joblib.load(model_file_path)
  File "/home/adminuser/venv/lib/python3.9/site-packages/joblib/numpy_pickle.py", line 650, in load
    with open(filename, 'rb') as f:
FileNotFoundError: [Errno 2] No such file or directory: 'D:/MPS Analytics/CardioRiskAnalyzer/models/random_forest_model.pkl'
2024-02-10 22:22:39.112 503 GET /script-health-check (10.12.118.41) 149.81ms
2024-02-10 22:22:43.849 Uncaught app exception
Traceback (most recent call last):
  File "/home/adminuser/venv/lib/python3.9/site-packages/streamlit/runtime/scriptrunner/script_runner.py", line 534, in _run_script
    exec(code, module.__dict__)
  File "/mount/src/cardioriskanalyzer/scripts/heart_disease_prediction.py", line 16, in <module>
    random_forest = joblib.load(model_file_path)
  File "/home/adminuser/venv/lib/python3.9/site-packages/joblib/numpy_pickle.py", line 650, in load
    with open(filename, 'rb') as f:
FileNotFoundError: [Errno 2] No such file or directory: 'D:/MPS Analytics/CardioRiskAnalyzer/models/random_forest_model.pkl'
2024-02-10 22:22:43.887 503 GET /script-health-check (10.12.118.41) 38.68ms
2024-02-10 22:22:48.866 Uncaught app exception
Traceback (most recent call last):
  File "/home/adminuser/venv/lib/python3.9/site-packages/streamlit/runtime/scriptrunner/script_runner.py", line 534, in _run_script
    exec(code, module.__dict__)
  File "/mount/src/cardioriskanalyzer/scripts/heart_disease_prediction.py", line 16, in <module>
    random_forest = joblib.load(model_file_path)
  File "/home/adminuser/venv/lib/python3.9/site-packages/joblib/numpy_pickle.py", line 650, in load
    with open(filename, 'rb') as f:
FileNotFoundError: [Errno 2] No such file or directory: 'D:/MPS Analytics/CardioRiskAnalyzer/models/random_forest_model.pkl'
2024-02-10 22:22:48.906 503 GET /script-health-check (10.12.118.41) 41.29ms
2024-02-10 22:22:53.845 Uncaught app exception
Traceback (most recent call last):
  File "/home/adminuser/venv/lib/python3.9/site-packages/streamlit/runtime/scriptrunner/script_runner.py", line 534, in _run_script
    exec(code, module.__dict__)
  File "/mount/src/cardioriskanalyzer/scripts/heart_disease_prediction.py", line 16, in <module>
    random_forest = joblib.load(model_file_path)
  File "/home/adminuser/venv/lib/python3.9/site-packages/joblib/numpy_pickle.py", line 650, in load
    with open(filename, 'rb') as f:
FileNotFoundError: [Errno 2] No such file or directory: 'D:/MPS Analytics/CardioRiskAnalyzer/models/random_forest_model.pkl'
2024-02-10 22:22:53.972 503 GET /script-health-check (10.12.118.41) 129.32ms
2024-02-10 22:22:58.866 503 GET /script-health-check (10.12.118.41) 1.99ms
2024-02-10 22:22:58.865 Uncaught app exception
Traceback (most recent call last):
  File "/home/adminuser/venv/lib/python3.9/site-packages/streamlit/runtime/scriptrunner/script_runner.py", line 534, in _run_script
    exec(code, module.__dict__)
  File "/mount/src/cardioriskanalyzer/scripts/heart_disease_prediction.py", line 16, in <module>
    random_forest = joblib.load(model_file_path)
  File "/home/adminuser/venv/lib/python3.9/site-packages/joblib/numpy_pickle.py", line 650, in load
    with open(filename, 'rb') as f:
FileNotFoundError: [Errno 2] No such file or directory: 'D:/MPS Analytics/CardioRiskAnalyzer/models/random_forest_model.pkl'
2024-02-10 22:23:03.892 Uncaught app exception
Traceback (most recent call last):
  File "/home/adminuser/venv/lib/python3.9/site-packages/streamlit/runtime/scriptrunner/script_runner.py", line 534, in _run_script
    exec(code, module.__dict__)
  File "/mount/src/cardioriskanalyzer/scripts/heart_disease_prediction.py", line 16, in <module>
    random_forest = joblib.load(model_file_path)
  File "/home/adminuser/venv/lib/python3.9/site-packages/joblib/numpy_pickle.py", line 650, in load
    with open(filename, 'rb') as f:
FileNotFoundError: [Errno 2] No such file or directory: 'D:/MPS Analytics/CardioRiskAnalyzer/models/random_forest_model.pkl'
2024-02-10 22:23:04.022 503 GET /script-health-check (10.12.118.41) 131.28ms
2024-02-10 22:23:08.959 503 GET /script-health-check (10.12.118.41) 1.76ms
2024-02-10 22:23:08.958 Uncaught app exception
Traceback (most recent call last):
  File "/home/adminuser/venv/lib/python3.9/site-packages/streamlit/runtime/scriptrunner/script_runner.py", line 534, in _run_script
    exec(code, module.__dict__)
  File "/mount/src/cardioriskanalyzer/scripts/heart_disease_prediction.py", line 16, in <module>
    random_forest = joblib.load(model_file_path)
  File "/home/adminuser/venv/lib/python3.9/site-packages/joblib/numpy_pickle.py", line 650, in load
    with open(filename, 'rb') as f:
FileNotFoundError: [Errno 2] No such file or directory: 'D:/MPS Analytics/CardioRiskAnalyzer/models/random_forest_model.pkl'
2024-02-10 22:23:13.937 503 GET /script-health-check (10.12.118.41) 2.35ms
2024-02-10 22:23:13.936 Uncaught app exception
Traceback (most recent call last):
  File "/home/adminuser/venv/lib/python3.9/site-packages/streamlit/runtime/scriptrunner/script_runner.py", line 534, in _run_script
    exec(code, module.__dict__)
  File "/mount/src/cardioriskanalyzer/scripts/heart_disease_prediction.py", line 16, in <module>
    random_forest = joblib.load(model_file_path)
  File "/home/adminuser/venv/lib/python3.9/site-packages/joblib/numpy_pickle.py", line 650, in load
    with open(filename, 'rb') as f:
FileNotFoundError: [Errno 2] No such file or directory: 'D:/MPS Analytics/CardioRiskAnalyzer/models/random_forest_model.pkl'
2024-02-10 22:23:18.881 503 GET /script-health-check (10.12.118.41) 2.22ms
2024-02-10 22:23:18.880 Uncaught app exception
Traceback (most recent call last):
  File "/home/adminuser/venv/lib/python3.9/site-packages/streamlit/runtime/scriptrunner/script_runner.py", line 534, in _run_script
    exec(code, module.__dict__)
  File "/mount/src/cardioriskanalyzer/scripts/heart_disease_prediction.py", line 16, in <module>
    random_forest = joblib.load(model_file_path)
  File "/home/adminuser/venv/lib/python3.9/site-packages/joblib/numpy_pickle.py", line 650, in load
    with open(filename, 'rb') as f:
FileNotFoundError: [Errno 2] No such file or directory: 'D:/MPS Analytics/CardioRiskAnalyzer/models/random_forest_model.pkl'
2024-02-10 22:23:23.923 503 GET /script-health-check (10.12.118.41) 2.23ms
2024-02-10 22:23:23.923 Uncaught app exception
Traceback (most recent call last):
  File "/home/adminuser/venv/lib/python3.9/site-packages/streamlit/runtime/scriptrunner/script_runner.py", line 534, in _run_script
    exec(code, module.__dict__)
  File "/mount/src/cardioriskanalyzer/scripts/heart_disease_prediction.py", line 16, in <module>
    random_forest = joblib.load(model_file_path)
  File "/home/adminuser/venv/lib/python3.9/site-packages/joblib/numpy_pickle.py", line 650, in load
    with open(filename, 'rb') as f:
FileNotFoundError: [Errno 2] No such file or directory: 'D:/MPS Analytics/CardioRiskAnalyzer/models/random_forest_model.pkl'
2024-02-10 22:23:28.854 503 GET /script-health-check (10.12.118.41) 2.21ms
2024-02-10 22:23:28.853 Uncaught app exception
Traceback (most recent call last):
  File "/home/adminuser/venv/lib/python3.9/site-packages/streamlit/runtime/scriptrunner/script_runner.py", line 534, in _run_script
    exec(code, module.__dict__)
  File "/mount/src/cardioriskanalyzer/scripts/heart_disease_prediction.py", line 16, in <module>
    random_forest = joblib.load(model_file_path)
  File "/home/adminuser/venv/lib/python3.9/site-packages/joblib/numpy_pickle.py", line 650, in load
    with open(filename, 'rb') as f:
FileNotFoundError: [Errno 2] No such file or directory: 'D:/MPS Analytics/CardioRiskAnalyzer/models/random_forest_model.pkl'
2024-02-10 22:23:33.889 Uncaught app exception
Traceback (most recent call last):
  File "/home/adminuser/venv/lib/python3.9/site-packages/streamlit/runtime/scriptrunner/script_runner.py", line 534, in _run_script
    exec(code, module.__dict__)
  File "/mount/src/cardioriskanalyzer/scripts/heart_disease_prediction.py", line 16, in <module>
    random_forest = joblib.load(model_file_path)
  File "/home/adminuser/venv/lib/python3.9/site-packages/joblib/numpy_pickle.py", line 650, in load
    with open(filename, 'rb') as f:
FileNotFoundError: [Errno 2] No such file or directory: 'D:/MPS Analytics/CardioRiskAnalyzer/models/random_forest_model.pkl'
2024-02-10 22:23:34.028 503 GET /script-health-check (10.12.118.41) 141.00ms
2024-02-10 22:23:38.894 Uncaught app exception
Traceback (most recent call last):
  File "/home/adminuser/venv/lib/python3.9/site-packages/streamlit/runtime/scriptrunner/script_runner.py", line 534, in _run_script
    exec(code, module.__dict__)
  File "/mount/src/cardioriskanalyzer/scripts/heart_disease_prediction.py", line 16, in <module>
    random_forest = joblib.load(model_file_path)
  File "/home/adminuser/venv/lib/python3.9/site-packages/joblib/numpy_pickle.py", line 650, in load
    with open(filename, 'rb') as f:
FileNotFoundError: [Errno 2] No such file or directory: 'D:/MPS Analytics/CardioRiskAnalyzer/models/random_forest_model.pkl'
2024-02-10 22:23:39.064 503 GET /script-health-check (10.12.118.41) 171.21ms
2024-02-10 22:23:43.893 Uncaught app exception
Traceback (most recent call last):
  File "/home/adminuser/venv/lib/python3.9/site-packages/streamlit/runtime/scriptrunner/script_runner.py", line 534, in _run_script
    exec(code, module.__dict__)
  File "/mount/src/cardioriskanalyzer/scripts/heart_disease_prediction.py", line 16, in <module>
    random_forest = joblib.load(model_file_path)
  File "/home/adminuser/venv/lib/python3.9/site-packages/joblib/numpy_pickle.py", line 650, in load
    with open(filename, 'rb') as f:
FileNotFoundError: [Errno 2] No such file or directory: 'D:/MPS Analytics/CardioRiskAnalyzer/models/random_forest_model.pkl'
2024-02-10 22:23:44.090 503 GET /script-health-check (10.12.118.41) 198.93ms
2024-02-10 22:23:48.949 Uncaught app exception
Traceback (most recent call last):
  File "/home/adminuser/venv/lib/python3.9/site-packages/streamlit/runtime/scriptrunner/script_runner.py", line 534, in _run_script
    exec(code, module.__dict__)
  File "/mount/src/cardioriskanalyzer/scripts/heart_disease_prediction.py", line 16, in <module>
    random_forest = joblib.load(model_file_path)
  File "/home/adminuser/venv/lib/python3.9/site-packages/joblib/numpy_pickle.py", line 650, in load
    with open(filename, 'rb') as f:
FileNotFoundError: [Errno 2] No such file or directory: 'D:/MPS Analytics/CardioRiskAnalyzer/models/random_forest_model.pkl'
2024-02-10 22:23:49.115 503 GET /script-health-check (10.12.118.41) 168.14ms
2024-02-10 22:23:53.888 Uncaught app exception
Traceback (most recent call last):
  File "/home/adminuser/venv/lib/python3.9/site-packages/streamlit/runtime/scriptrunner/script_runner.py", line 534, in _run_script
    exec(code, module.__dict__)
  File "/mount/src/cardioriskanalyzer/scripts/heart_disease_prediction.py", line 16, in <module>
    random_forest = joblib.load(model_file_path)
  File "/home/adminuser/venv/lib/python3.9/site-packages/joblib/numpy_pickle.py", line 650, in load
    with open(filename, 'rb') as f:
FileNotFoundError: [Errno 2] No such file or directory: 'D:/MPS Analytics/CardioRiskAnalyzer/models/random_forest_model.pkl'
2024-02-10 22:23:54.078 503 GET /script-health-check (10.12.118.41) 191.50ms
2024-02-10 22:23:58.878 Uncaught app exception
Traceback (most recent call last):
  File "/home/adminuser/venv/lib/python3.9/site-packages/streamlit/runtime/scriptrunner/script_runner.py", line 534, in _run_script
    exec(code, module.__dict__)
  File "/mount/src/cardioriskanalyzer/scripts/heart_disease_prediction.py", line 16, in <module>
    random_forest = joblib.load(model_file_path)
  File "/home/adminuser/venv/lib/python3.9/site-packages/joblib/numpy_pickle.py", line 650, in load
    with open(filename, 'rb') as f:
FileNotFoundError: [Errno 2] No such file or directory: 'D:/MPS Analytics/CardioRiskAnalyzer/models/random_forest_model.pkl'
2024-02-10 22:23:59.034 503 GET /script-health-check (10.12.118.41) 158.33ms
2024-02-10 22:24:03.858 503 GET /script-health-check (10.12.118.41) 2.38ms
2024-02-10 22:24:03.857 Uncaught app exception
Traceback (most recent call last):
  File "/home/adminuser/venv/lib/python3.9/site-packages/streamlit/runtime/scriptrunner/script_runner.py", line 534, in _run_script
    exec(code, module.__dict__)
  File "/mount/src/cardioriskanalyzer/scripts/heart_disease_prediction.py", line 16, in <module>
    random_forest = joblib.load(model_file_path)
  File "/home/adminuser/venv/lib/python3.9/site-packages/joblib/numpy_pickle.py", line 650, in load
    with open(filename, 'rb') as f:
FileNotFoundError: [Errno 2] No such file or directory: 'D:/MPS Analytics/CardioRiskAnalyzer/models/random_forest_model.pkl'
2024-02-10 22:24:08.905 Uncaught app exception
Traceback (most recent call last):
  File "/home/adminuser/venv/lib/python3.9/site-packages/streamlit/runtime/scriptrunner/script_runner.py", line 534, in _run_script
    exec(code, module.__dict__)
  File "/mount/src/cardioriskanalyzer/scripts/heart_disease_prediction.py", line 16, in <module>
    random_forest = joblib.load(model_file_path)
  File "/home/adminuser/venv/lib/python3.9/site-packages/joblib/numpy_pickle.py", line 650, in load
    with open(filename, 'rb') as f:
FileNotFoundError: [Errno 2] No such file or directory: 'D:/MPS Analytics/CardioRiskAnalyzer/models/random_forest_model.pkl'
2024-02-10 22:24:09.099 503 GET /script-health-check (10.12.118.41) 196.56ms
2024-02-10 22:24:13.908 Uncaught app exception
Traceback (most recent call last):
  File "/home/adminuser/venv/lib/python3.9/site-packages/streamlit/runtime/scriptrunner/script_runner.py", line 534, in _run_script
    exec(code, module.__dict__)
  File "/mount/src/cardioriskanalyzer/scripts/heart_disease_prediction.py", line 16, in <module>
    random_forest = joblib.load(model_file_path)
  File "/home/adminuser/venv/lib/python3.9/site-packages/joblib/numpy_pickle.py", line 650, in load
    with open(filename, 'rb') as f:
FileNotFoundError: [Errno 2] No such file or directory: 'D:/MPS Analytics/CardioRiskAnalyzer/models/random_forest_model.pkl'
2024-02-10 22:24:14.027 503 GET /script-health-check (10.12.118.41) 120.00ms
2024-02-10 22:24:18.834 Uncaught app exception
Traceback (most recent call last):
  File "/home/adminuser/venv/lib/python3.9/site-packages/streamlit/runtime/scriptrunner/script_runner.py", line 534, in _run_script
    exec(code, module.__dict__)
  File "/mount/src/cardioriskanalyzer/scripts/heart_disease_prediction.py", line 16, in <module>
    random_forest = joblib.load(model_file_path)
  File "/home/adminuser/venv/lib/python3.9/site-packages/joblib/numpy_pickle.py", line 650, in load
    with open(filename, 'rb') as f:
FileNotFoundError: [Errno 2] No such file or directory: 'D:/MPS Analytics/CardioRiskAnalyzer/models/random_forest_model.pkl'
2024-02-10 22:24:18.950 503 GET /script-health-check (10.12.118.41) 117.22ms
2024-02-10 22:24:23.933 503 GET /script-health-check (10.12.118.41) 2.30ms
2024-02-10 22:24:23.933 Uncaught app exception
Traceback (most recent call last):
  File "/home/adminuser/venv/lib/python3.9/site-packages/streamlit/runtime/scriptrunner/script_runner.py", line 534, in _run_script
    exec(code, module.__dict__)
  File "/mount/src/cardioriskanalyzer/scripts/heart_disease_prediction.py", line 16, in <module>
    random_forest = joblib.load(model_file_path)
  File "/home/adminuser/venv/lib/python3.9/site-packages/joblib/numpy_pickle.py", line 650, in load
    with open(filename, 'rb') as f:
FileNotFoundError: [Errno 2] No such file or directory: 'D:/MPS Analytics/CardioRiskAnalyzer/models/random_forest_model.pkl'
2024-02-10 22:24:28.900 Uncaught app exception
Traceback (most recent call last):
  File "/home/adminuser/venv/lib/python3.9/site-packages/streamlit/runtime/scriptrunner/script_runner.py", line 534, in _run_script
    exec(code, module.__dict__)
  File "/mount/src/cardioriskanalyzer/scripts/heart_disease_prediction.py", line 16, in <module>
    random_forest = joblib.load(model_file_path)
  File "/home/adminuser/venv/lib/python3.9/site-packages/joblib/numpy_pickle.py", line 650, in load
    with open(filename, 'rb') as f:
FileNotFoundError: [Errno 2] No such file or directory: 'D:/MPS Analytics/CardioRiskAnalyzer/models/random_forest_model.pkl'
2024-02-10 22:24:29.028 503 GET /script-health-check (10.12.118.41) 129.59ms
2024-02-10 22:24:33.899 Uncaught app exception
Traceback (most recent call last):
  File "/home/adminuser/venv/lib/python3.9/site-packages/streamlit/runtime/scriptrunner/script_runner.py", line 534, in _run_script
    exec(code, module.__dict__)
  File "/mount/src/cardioriskanalyzer/scripts/heart_disease_prediction.py", line 16, in <module>
    random_forest = joblib.load(model_file_path)
  File "/home/adminuser/venv/lib/python3.9/site-packages/joblib/numpy_pickle.py", line 650, in load
    with open(filename, 'rb') as f:
FileNotFoundError: [Errno 2] No such file or directory: 'D:/MPS Analytics/CardioRiskAnalyzer/models/random_forest_model.pkl'
2024-02-10 22:24:33.900 503 GET /script-health-check (10.12.118.41) 2.42ms
2024-02-10 22:24:38.962 503 GET /script-health-check (10.12.118.41) 2.12ms
2024-02-10 22:24:38.961 Uncaught app exception
Traceback (most recent call last):
  File "/home/adminuser/venv/lib/python3.9/site-packages/streamlit/runtime/scriptrunner/script_runner.py", line 534, in _run_script
    exec(code, module.__dict__)
  File "/mount/src/cardioriskanalyzer/scripts/heart_disease_prediction.py", line 16, in <module>
    random_forest = joblib.load(model_file_path)
  File "/home/adminuser/venv/lib/python3.9/site-packages/joblib/numpy_pickle.py", line 650, in load
    with open(filename, 'rb') as f:
FileNotFoundError: [Errno 2] No such file or directory: 'D:/MPS Analytics/CardioRiskAnalyzer/models/random_forest_model.pkl'
2024-02-10 22:24:43.841 Uncaught app exception
Traceback (most recent call last):
  File "/home/adminuser/venv/lib/python3.9/site-packages/streamlit/runtime/scriptrunner/script_runner.py", line 534, in _run_script
    exec(code, module.__dict__)
  File "/mount/src/cardioriskanalyzer/scripts/heart_disease_prediction.py", line 16, in <module>
    random_forest = joblib.load(model_file_path)
  File "/home/adminuser/venv/lib/python3.9/site-packages/joblib/numpy_pickle.py", line 650, in load
    with open(filename, 'rb') as f:
FileNotFoundError: [Errno 2] No such file or directory: 'D:/MPS Analytics/CardioRiskAnalyzer/models/random_forest_model.pkl'
2024-02-10 22:24:43.995 503 GET /script-health-check (10.12.118.41) 156.19ms
2024-02-10 22:24:48.892 Uncaught app exception
Traceback (most recent call last):
  File "/home/adminuser/venv/lib/python3.9/site-packages/streamlit/runtime/scriptrunner/script_runner.py", line 534, in _run_script
    exec(code, module.__dict__)
  File "/mount/src/cardioriskanalyzer/scripts/heart_disease_prediction.py", line 16, in <module>
    random_forest = joblib.load(model_file_path)
  File "/home/adminuser/venv/lib/python3.9/site-packages/joblib/numpy_pickle.py", line 650, in load
    with open(filename, 'rb') as f:
FileNotFoundError: [Errno 2] No such file or directory: 'D:/MPS Analytics/CardioRiskAnalyzer/models/random_forest_model.pkl'
2024-02-10 22:24:49.012 503 GET /script-health-check (10.12.118.41) 121.13ms
2024-02-10 22:24:53.958 Uncaught app exception
Traceback (most recent call last):
  File "/home/adminuser/venv/lib/python3.9/site-packages/streamlit/runtime/scriptrunner/script_runner.py", line 534, in _run_script
    exec(code, module.__dict__)
  File "/mount/src/cardioriskanalyzer/scripts/heart_disease_prediction.py", line 16, in <module>
    random_forest = joblib.load(model_file_path)
  File "/home/adminuser/venv/lib/python3.9/site-packages/joblib/numpy_pickle.py", line 650, in load
    with open(filename, 'rb') as f:
FileNotFoundError: [Errno 2] No such file or directory: 'D:/MPS Analytics/CardioRiskAnalyzer/models/random_forest_model.pkl'
2024-02-10 22:24:53.959 503 GET /script-health-check (10.12.118.41) 2.56ms
2024-02-10 22:24:58.909 Uncaught app exception
Traceback (most recent call last):
  File "/home/adminuser/venv/lib/python3.9/site-packages/streamlit/runtime/scriptrunner/script_runner.py", line 534, in _run_script
    exec(code, module.__dict__)
  File "/mount/src/cardioriskanalyzer/scripts/heart_disease_prediction.py", line 16, in <module>
    random_forest = joblib.load(model_file_path)
  File "/home/adminuser/venv/lib/python3.9/site-packages/joblib/numpy_pickle.py", line 650, in load
    with open(filename, 'rb') as f:
FileNotFoundError: [Errno 2] No such file or directory: 'D:/MPS Analytics/CardioRiskAnalyzer/models/random_forest_model.pkl'
2024-02-10 22:24:59.024 503 GET /script-health-check (10.12.118.41) 117.19ms
2024-02-10 22:25:03.906 Uncaught app exception
Traceback (most recent call last):
  File "/home/adminuser/venv/lib/python3.9/site-packages/streamlit/runtime/scriptrunner/script_runner.py", line 534, in _run_script
    exec(code, module.__dict__)
  File "/mount/src/cardioriskanalyzer/scripts/heart_disease_prediction.py", line 16, in <module>
    random_forest = joblib.load(model_file_path)
  File "/home/adminuser/venv/lib/python3.9/site-packages/joblib/numpy_pickle.py", line 650, in load
    with open(filename, 'rb') as f:
FileNotFoundError: [Errno 2] No such file or directory: 'D:/MPS Analytics/CardioRiskAnalyzer/models/random_forest_model.pkl'
2024-02-10 22:25:04.092 503 GET /script-health-check (10.12.118.41) 188.25ms
2024-02-10 22:25:08.909 Uncaught app exception
Traceback (most recent call last):
  File "/home/adminuser/venv/lib/python3.9/site-packages/streamlit/runtime/scriptrunner/script_runner.py", line 534, in _run_script
    exec(code, module.__dict__)
  File "/mount/src/cardioriskanalyzer/scripts/heart_disease_prediction.py", line 16, in <module>
    random_forest = joblib.load(model_file_path)
  File "/home/adminuser/venv/lib/python3.9/site-packages/joblib/numpy_pickle.py", line 650, in load
    with open(filename, 'rb') as f:
FileNotFoundError: [Errno 2] No such file or directory: 'D:/MPS Analytics/CardioRiskAnalyzer/models/random_forest_model.pkl'
2024-02-10 22:25:08.964 503 GET /script-health-check (10.12.118.41) 56.80ms
2024-02-10 22:25:13.880 503 GET /script-health-check (10.12.118.41) 2.17ms
2024-02-10 22:25:13.880 Uncaught app exception
Traceback (most recent call last):
  File "/home/adminuser/venv/lib/python3.9/site-packages/streamlit/runtime/scriptrunner/script_runner.py", line 534, in _run_script
    exec(code, module.__dict__)
  File "/mount/src/cardioriskanalyzer/scripts/heart_disease_prediction.py", line 16, in <module>
    random_forest = joblib.load(model_file_path)
  File "/home/adminuser/venv/lib/python3.9/site-packages/joblib/numpy_pickle.py", line 650, in load
    with open(filename, 'rb') as f:
FileNotFoundError: [Errno 2] No such file or directory: 'D:/MPS Analytics/CardioRiskAnalyzer/models/random_forest_model.pkl'
2024-02-10 22:25:18.927 Uncaught app exception
Traceback (most recent call last):
  File "/home/adminuser/venv/lib/python3.9/site-packages/streamlit/runtime/scriptrunner/script_runner.py", line 534, in _run_script
    exec(code, module.__dict__)
  File "/mount/src/cardioriskanalyzer/scripts/heart_disease_prediction.py", line 16, in <module>
    random_forest = joblib.load(model_file_path)
  File "/home/adminuser/venv/lib/python3.9/site-packages/joblib/numpy_pickle.py", line 650, in load
    with open(filename, 'rb') as f:
FileNotFoundError: [Errno 2] No such file or directory: 'D:/MPS Analytics/CardioRiskAnalyzer/models/random_forest_model.pkl'
2024-02-10 22:25:18.927 503 GET /script-health-check (10.12.118.41) 1.86ms
2024-02-10 22:25:23.968 Uncaught app exception
Traceback (most recent call last):
  File "/home/adminuser/venv/lib/python3.9/site-packages/streamlit/runtime/scriptrunner/script_runner.py", line 534, in _run_script
    exec(code, module.__dict__)
  File "/mount/src/cardioriskanalyzer/scripts/heart_disease_prediction.py", line 16, in <module>
    random_forest = joblib.load(model_file_path)
  File "/home/adminuser/venv/lib/python3.9/site-packages/joblib/numpy_pickle.py", line 650, in load
    with open(filename, 'rb') as f:
FileNotFoundError: [Errno 2] No such file or directory: 'D:/MPS Analytics/CardioRiskAnalyzer/models/random_forest_model.pkl'
2024-02-10 22:25:24.144 503 GET /script-health-check (10.12.118.41) 178.80ms
2024-02-10 22:25:28.914 Uncaught app exception
Traceback (most recent call last):
  File "/home/adminuser/venv/lib/python3.9/site-packages/streamlit/runtime/scriptrunner/script_runner.py", line 534, in _run_script
    exec(code, module.__dict__)
  File "/mount/src/cardioriskanalyzer/scripts/heart_disease_prediction.py", line 16, in <module>
    random_forest = joblib.load(model_file_path)
  File "/home/adminuser/venv/lib/python3.9/site-packages/joblib/numpy_pickle.py", line 650, in load
    with open(filename, 'rb') as f:
FileNotFoundError: [Errno 2] No such file or directory: 'D:/MPS Analytics/CardioRiskAnalyzer/models/random_forest_model.pkl'
2024-02-10 22:25:28.915 503 GET /script-health-check (10.12.118.41) 2.56ms
2024-02-10 22:25:33.894 Uncaught app exception
Traceback (most recent call last):
  File "/home/adminuser/venv/lib/python3.9/site-packages/streamlit/runtime/scriptrunner/script_runner.py", line 534, in _run_script
    exec(code, module.__dict__)
  File "/mount/src/cardioriskanalyzer/scripts/heart_disease_prediction.py", line 16, in <module>
    random_forest = joblib.load(model_file_path)
  File "/home/adminuser/venv/lib/python3.9/site-packages/joblib/numpy_pickle.py", line 650, in load
    with open(filename, 'rb') as f:
FileNotFoundError: [Errno 2] No such file or directory: 'D:/MPS Analytics/CardioRiskAnalyzer/models/random_forest_model.pkl'
2024-02-10 22:25:34.023 503 GET /script-health-check (10.12.118.41) 131.77ms
2024-02-10 22:25:38.866 503 GET /script-health-check (10.12.118.41) 1.60ms
2024-02-10 22:25:38.866 Uncaught app exception
Traceback (most recent call last):
  File "/home/adminuser/venv/lib/python3.9/site-packages/streamlit/runtime/scriptrunner/script_runner.py", line 534, in _run_script
    exec(code, module.__dict__)
  File "/mount/src/cardioriskanalyzer/scripts/heart_disease_prediction.py", line 16, in <module>
    random_forest = joblib.load(model_file_path)
  File "/home/adminuser/venv/lib/python3.9/site-packages/joblib/numpy_pickle.py", line 650, in load
    with open(filename, 'rb') as f:
FileNotFoundError: [Errno 2] No such file or directory: 'D:/MPS Analytics/CardioRiskAnalyzer/models/random_forest_model.pkl'